<?xml version="1.0" ?>
<robot name="turtlebot3_waffle_cam" xmlns:xacro="http://ros.org/wiki/xacro">
  
  <material name="black"><color rgba="0.0 0.0 0.0 1.0"/></material>
  <material name="dark"><color rgba="0.3 0.3 0.3 1.0"/></material>
  <material name="light_black"><color rgba="0.4 0.4 0.4 1.0"/></material>
  <material name="blue"><color rgba="0.0 0.0 0.8 1.0"/></material>
  <material name="green"><color rgba="0.0 0.8 0.0 1.0"/></material>
  <material name="grey"><color rgba="0.5 0.5 0.5 1.0"/></material>
  <material name="orange"><color rgba="1.0 0.4235 0.0392 1.0"/></material>
  <material name="brown"><color rgba="0.8706 0.8118 0.7647 1.0"/></material>
  <material name="red"><color rgba="0.8 0.0 0.0 1.0"/></material>
  <material name="white"><color rgba="1.0 1.0 1.0 1.0"/></material>

  <link name="base_footprint"/>

  <joint name="base_joint" type="fixed">
    <parent link="base_footprint"/>
    <child link="base_link"/>
    <origin xyz="0.0 0.0 0.010" rpy="0 0 0"/>
  </joint>

  <link name="base_link">
    <visual>
      <origin xyz="-0.032 0 0.0" rpy="0 0 0"/>
      <geometry>
        <mesh filename="package://turtlebot3_description/meshes/bases/waffle_base.stl" scale="0.001 0.001 0.001"/>
      </geometry>
      <material name="light_black"/>
    </visual>
    <collision>
      <origin xyz="-0.032 0 0.070" rpy="0 0 0"/>
      <geometry>
        <box size="0.140 0.140 0.143"/>
      </geometry>
    </collision>
    <inertial>
      <origin xyz="0 0 0" rpy="0 0 0"/>
      <mass value="8.2573504e-01"/>
      <inertia ixx="2.2124416e-03" ixy="-1.2294101e-05" ixz="3.4938785e-05" iyy="2.1193702e-03" iyz="-5.0120904e-06" izz="2.0064271e-03" />
    </inertial>
  </link>

  <joint name="wheel_left_joint" type="continuous">
    <parent link="base_link"/>
    <child link="wheel_left_link"/>
    <origin xyz="0.0 0.08 0.023" rpy="-1.57 0 0"/>
    <axis xyz="0 0 1"/>
  </joint>

  <link name="wheel_left_link">
    <visual>
      <origin xyz="0 0 0" rpy="1.57 0 0"/>
      <geometry>
        <mesh filename="package://turtlebot3_description/meshes/wheels/left_tire.stl" scale="0.001 0.001 0.001"/>
      </geometry>
      <material name="dark"/>
    </visual>
    <collision>
      <origin xyz="0 0 0" rpy="0 0 0"/>
      <geometry>
        <cylinder length="0.018" radius="0.033"/>
      </geometry>
    </collision>
    <inertial>
      <origin xyz="0 0 0" />
      <mass value="2.8498940e-02" />
      <inertia ixx="1.1175580e-05" ixy="-4.2369783e-11" ixz="-5.9381719e-09" iyy="1.1192413e-05" iyz="-1.4400107e-11" izz="2.0712558e-05" />
    </inertial>
  </link>

  <joint name="wheel_right_joint" type="continuous">
    <parent link="base_link"/>
    <child link="wheel_right_link"/>
    <origin xyz="0.0 -0.080 0.023" rpy="-1.57 0 0"/>
    <axis xyz="0 0 1"/>
  </joint>

  <link name="wheel_right_link">
    <visual>
      <origin xyz="0 0 0" rpy="1.57 0 0"/>
      <geometry>
        <mesh filename="package://turtlebot3_description/meshes/wheels/right_tire.stl" scale="0.001 0.001 0.001"/>
      </geometry>
      <material name="dark"/>
    </visual>
    <collision>
      <origin xyz="0 0 0" rpy="0 0 0"/>
      <geometry>
        <cylinder length="0.018" radius="0.033"/>
      </geometry>
    </collision>
    <inertial>
      <origin xyz="0 0 0" />
      <mass value="2.8498940e-02" />
      <inertia ixx="1.1175580e-05" ixy="-4.2369783e-11" ixz="-5.9381719e-09" iyy="1.1192413e-05" iyz="-1.4400107e-11" izz="2.0712558e-05" />
    </inertial>
  </link>

  <joint name="caster_back_joint" type="fixed">
    <parent link="base_link"/>
    <child link="caster_back_link"/>
    <origin xyz="-0.081 0 -0.004" rpy="-1.57 0 0"/>
  </joint>

  <link name="caster_back_link">
    <collision>
      <origin xyz="0 0.001 0" rpy="0 0 0"/>
      <geometry>
        <sphere radius="0.005"/>
      </geometry>
    </collision>
    <inertial>
      <origin xyz="0 0 0" />
      <mass value="0.005" />
      <inertia ixx="0.001" ixy="0.0" ixz="0.0" iyy="0.001" iyz="0.0" izz="0.001" />
    </inertial>
  </link>
  
  <gazebo reference="caster_back_link">
    <mu1>0.0</mu1>
    <mu2>0.0</mu2>
    <kp>1000000.0</kp>
    <kd>100.0</kd>
    <minDepth>0.001</minDepth>
    <maxVel>1.0</maxVel>
    <material>Gazebo/FlatBlack</material>
  </gazebo>

  <joint name="imu_joint" type="fixed">
    <parent link="base_link"/>
    <child link="imu_link"/>
    <origin xyz="-0.032 0 0.068" rpy="0 0 0"/>
  </joint>
  <link name="imu_link"/>

  <joint name="scan_joint" type="fixed">
    <parent link="base_link"/>
    <child link="base_scan"/>
    <origin xyz="-0.032 0 0.172" rpy="0 0 0"/>
  </joint>

  <link name="base_scan">
    <visual>
      <origin xyz="0 0 0.0" rpy="0 0 0"/>
      <geometry>
        <mesh filename="package://turtlebot3_description/meshes/sensors/lds.stl" scale="0.001 0.001 0.001"/>
      </geometry>
      <material name="dark"/>
    </visual>
    <collision>
      <origin xyz="0.015 0 -0.0065" rpy="0 0 0"/>
      <geometry>
        <cylinder length="0.0315" radius="0.055"/>
      </geometry>
    </collision>
    <inertial>
      <mass value="0.114" />
      <origin xyz="0 0 0" />
      <inertia ixx="0.001" ixy="0.0" ixz="0.0" iyy="0.001" iyz="0.0" izz="0.001" />
    </inertial>
  </link>
  
  <joint name="camera_joint" type="fixed">
    <origin xyz="0.040 -0.000 0.110" rpy="0 0 0"/>
    <parent link="base_link"/>
    <child link="camera_link"/>
  </joint>

  <link name="camera_link">
    <visual>
      <origin xyz="0.005 0.000 0.013" rpy="0 0 0"/>
      <geometry>
        <box size="0.015 0.030 0.027"/>
      </geometry>
      <material name="red"/>
    </visual>
    </link>

  <joint name="camera_rgb_joint" type="fixed">
    <origin xyz="0.003 0.000 0.009" rpy="0 0 0"/>
    <parent link="camera_link"/>
    <child link="camera_rgb_frame"/>
  </joint>
  <link name="camera_rgb_frame"/>

  <joint name="camera_rgb_optical_joint" type="fixed">
    <origin xyz="0 0 0" rpy="-1.5707 0 -1.57"/>
    <parent link="camera_rgb_frame"/>
    <child link="camera_rgb_optical_frame"/>
  </joint>
  <link name="camera_rgb_optical_frame"/>

  <gazebo reference="camera_rgb_frame">
  <sensor type="camera" name="waffle_camera">
      <always_on>true</always_on>
      <visualize>true</visualize>
      <update_rate>30.0</update_rate>
      <camera>
        <horizontal_fov>1.08</horizontal_fov>
        <image><width>640</width><height>480</height><format>R8G8B8</format></image>
        <clip><near>0.03</near><far>100</far></clip>
      </camera>
      <plugin name="camera_controller" filename="libgazebo_ros_camera.so">
        <ros><remapping>~/image_raw:=camera/image_raw</remapping></ros>
        <frame_name>camera_rgb_optical_frame</frame_name>
      </plugin>
    </sensor>
  </gazebo>

  <gazebo>
    <plugin name="turtlebot3_diff_drive" filename="libgazebo_ros_diff_drive.so">
      <update_rate>30</update_rate>
      <left_joint>wheel_left_joint</left_joint>
      <right_joint>wheel_right_joint</right_joint>
      <wheel_separation>0.160</wheel_separation>
      <wheel_diameter>0.066</wheel_diameter>
      <max_wheel_torque>20</max_wheel_torque>
      <max_wheel_acceleration>1.0</max_wheel_acceleration>
      <command_topic>cmd_vel</command_topic>
      <publish_odom>true</publish_odom>
      <publish_odom_tf>true</publish_odom_tf>
      <robot_base_frame>base_footprint</robot_base_frame>
    </plugin>
  </gazebo>

</robot>
